Workbook

Sheet Start Here
A1: BIBLE JOURNEY · MASTER CANON LEDGER v1.0
A2: Single source of truth unifying Canon Maps v0.1–v0.9. Tracks 66 canonical books, 1,189 chapters, source-map provenance, editorial uncertainty, and release gates.
A4: Master purpose: unify coverage and editorial traceability without pretending that every book or passage has a single settled chronological placement. Canonical completeness, transparent uncertainty, and intact Scripture remain non-negotiable.
A6: Canonical Chapters | C6: Books Fully Covered | E6: Source Maps Unified | G6: Master CRS Records | I6: Master Reading Blocks
A7: =COUNTA('Master Chapter Coverage'!A5:A2000) -> 1189 | C7: =COUNTIF('Book Summary'!G5:G100,"PASS") -> 66 | E7: =COUNTA('Map Registry'!A5:A50) -> 9 | G7: =COUNTA('Master CRS Ledger'!A5:A1000) -> 514 | I7: =COUNTA('Master Reading Blocks'!A5:A1500) -> 667
A10: Open Editorial Decisions | C10: Duplicate Canon Keys | E10: Missing Canon Keys | G10: Source Registry Records | I10: Dependency / Policy Records
A11: =COUNTIF('Open Decisions Master'!J5:J500,"Open") -> 85 | C11: =COUNTIF('Master Chapter Coverage'!P5:P2000,"DUPLICATE") -> 0 | E11: =COUNTIF('Master Chapter Coverage'!P5:P2000,"MISSING") -> 0 | G11: =COUNTA('Source Registry'!A5:A500) -> 118 | I11: =COUNTA('Master Link Registry'!A5:A1000) -> 337
A14: What v1.0 proves | F14: Immediate leadership decision
A15: • Every chapter in the 66-book canon has one master coverage record. • The master preserves provenance: every CRS, block, source, decision, and dependency points back to its originating map. • Parallel accounts, poetry, prophetic blocks, letters, and apocalyptic literature remain intact rather than being merged into synthetic Scripture. • The master does not declare the final event-by-event global stream resolved. It identifies where a Harmonization Engine must attach parallel and contextual records. • Release readiness is governed by audit gates, not by visual completeness alone. | F15: The canon is now mapped at coverage level. The next critical build is not more chapter mapping; it is a Harmonization Engine that determines the final user-facing order of connected CRS records. It must resolve, with explicit confidence and profiles: 1. Samuel / Kings / Chronicles interleaving. 2. Prophets within reigns and historical horizons. 3. Psalms and wisdom as evidence-scored connections. 4. Gospel parallel accounts. 5. Acts and epistolary placements. 6. Canonical fallback and literary-sequence behavior.
A23: Release Gate | B23: Current Status | C23: Owner | D23: Why It Matters | E23: Next Action
A24: Master chapter coverage | B24: PASS | C24: Editorial QA | D24: A Bible Stream cannot claim completeness with missing or duplicate canonical keys. | E24: Maintain this audit automatically on every import.
A25: Verse-level continuity | B25: BLOCKED | C25: Editorial + Engineering | D25: Chapter mapping cannot detect missing/overlapping verse intervals, especially in Gospel segments and split chapters. | E25: Build PassageBlock / verse-interval validator.
A26: Cross-map harmonization | B26: BLOCKED | C26: Editorial Council | D26: Source maps contain valid components but not a finalized user-facing global event order. | E26: Create Harmonization Engine v1.0.
A27: Open-decision triage | B27: BLOCKED | C27: Editorial Council | D27: High-risk chronology and interpretive questions need policy, profile, or disclosure. | E27: Classify as resolve / disclose / out-of-scope.
A28: Translation licensing | B28: IN PROGRESS | C28: Legal + Partnerships | D28: Reader text availability depends on licensed translations and permitted display rules. | E28: Continue RVR60/NVI license pilot workflow; retain reference mode fallback.

Sheet Map Registry
A1: MAP REGISTRY
A2: Inventory of source workbooks merged into the Master Canon Ledger. Map-level counts are formula-driven from normalized master sheets.
A4: Map Version | B4: Map Name | C4: Source Workbook | D4: Scope | E4: Source Coverage Sheet | F4: Integration Stage | G4: Integration Gate | H4: CRS Count | I4: Block Count | J4: Chapter Coverage Count | K4: Open Decisions | L4: Load Status
A5: v0.1 | B5: Genesis to 2 Samuel | C5: Bible_Journey_Canon_Map_v0_1_Genesis_to_2Samuel.xlsx | D5: Genesis through 2 Samuel | E5: Chapter Map | F5: Canonical narrative spine | G5: Verse-level scene splits; David/Psalms linking policy | H5: =COUNTIF('Master CRS Ledger'!$A$5:$A$1000,A5) -> 116 | I5: =COUNTIF('Master Reading Blocks'!$A$5:$A$1500,A5) -> 135 | J5: =COUNTIF('Master Chapter Coverage'!$G$5:$G$2000,A5) -> 291 | K5: =COUNTIF('Open Decisions Master'!$A$5:$A$500,A5) -> 12 | L5: Imported
A6: v0.2 | B6: Chronicles, Psalms, Job, 1 Kings | C6: Bible_Journey_Canon_Map_v0_2_Chronicles_Psalms_Job_1Kings.xlsx | D6: 1 Chronicles, Psalms, Job, 1 Kings | E6: Chapter Map | F6: Parallel accounts, poetry, wisdom, United Monarchy | G6: Cross-map attachment to Samuel/Kings; Psalm evidence policy | H6: =COUNTIF('Master CRS Ledger'!$A$5:$A$1000,A6) -> 94 | I6: =COUNTIF('Master Reading Blocks'!$A$5:$A$1500,A6) -> 94 | J6: =COUNTIF('Master Chapter Coverage'!$G$5:$G$2000,A6) -> 243 | K6: =COUNTIF('Open Decisions Master'!$A$5:$A$500,A6) -> 14 | L6: Imported
A7: v0.3 | B7: 2 Chronicles, Wisdom, 2 Kings | C7: Bible_Journey_Canon_Map_v0_3_2Chronicles_Wisdom_2Kings.xlsx | D7: 2 Chronicles, Proverbs, Ecclesiastes, Song of Songs, 2 Kings | E7: Chapter Map | F7: Kingdom division and wisdom interlude | G7: Kings/Chronicles interleaving and wisdom placement disclosure | H7: =COUNTIF('Master CRS Ledger'!$A$5:$A$1000,A7) -> 47 | I7: =COUNTIF('Master Reading Blocks'!$A$5:$A$1500,A7) -> 67 | J7: =COUNTIF('Master Chapter Coverage'!$G$5:$G$2000,A7) -> 112 | K7: =COUNTIF('Open Decisions Master'!$A$5:$A$500,A7) -> 9 | L7: Imported
A8: v0.4 | B8: Prophets and Exile | C8: Bible_Journey_Canon_Map_v0_4_Prophets_Exile.xlsx | D8: Isaiah through Lamentations (mapped prophetic corpus) | E8: Chapter Map | F8: Prophets inside Israel/Judah history | G8: Prophetic placement, Jeremiah reordering, Isaiah horizons | H8: =COUNTIF('Master CRS Ledger'!$A$5:$A$1000,A8) -> 52 | I8: =COUNTIF('Master Reading Blocks'!$A$5:$A$1500,A8) -> 54 | J8: =COUNTIF('Master Chapter Coverage'!$G$5:$G$2000,A8) -> 166 | K8: =COUNTIF('Open Decisions Master'!$A$5:$A$500,A8) -> 9 | L8: Imported
A9: v0.5 | B9: Exile, Return, Persia | C9: Bible_Journey_Canon_Map_v0_5_Exile_Return_Persia.xlsx | D9: Habakkuk, Obadiah, Ezekiel, Daniel, Ezra, Nehemiah, Haggai, Zechariah, Malachi | E9: Coverage Audit | F9: Exile, return, Persian transition | G9: Dated prophetic splits, Ezra flash-forward handling, post-exilic placement | H9: =COUNTIF('Master CRS Ledger'!$A$5:$A$1000,A9) -> 46 | I9: =COUNTIF('Master Reading Blocks'!$A$5:$A$1500,A9) -> 46 | J9: =COUNTIF('Master Chapter Coverage'!$G$5:$G$2000,A9) -> 107 | K9: =COUNTIF('Open Decisions Master'!$A$5:$A$500,A9) -> 11 | L9: Imported
A10: v0.6 | B10: Esther and Intertestamental Bridge | C10: Bible_Journey_Canon_Map_v0_6_Esther_Intertestamental_Bridge.xlsx | D10: Esther plus historical bridge cards | E10: Coverage Audit | F10: Persian diaspora and historical bridge | G10: Canon-profile policy and historical context-card governance | H10: =COUNTIF('Master CRS Ledger'!$A$5:$A$1000,A10) -> 4 | I10: =COUNTIF('Master Reading Blocks'!$A$5:$A$1500,A10) -> 4 | J10: =COUNTIF('Master Chapter Coverage'!$G$5:$G$2000,A10) -> 10 | K10: =COUNTIF('Open Decisions Master'!$A$5:$A$500,A10) -> 8 | L10: Imported
A11: v0.7 | B11: Gospel Chronology | C11: Bible_Journey_Canon_Map_v0_7_Gospel_Chronology.xlsx | D11: Matthew, Mark, Luke, John | E11: Coverage Index | F11: Four-Gospel event engine | G11: Verse-level coverage QA and harmony policy approval | H11: =COUNTIF('Master CRS Ledger'!$A$5:$A$1000,A11) -> 90 | I11: =COUNTIF('Master Reading Blocks'!$A$5:$A$1500,A11) -> 202 | J11: =COUNTIF('Master Chapter Coverage'!$G$5:$G$2000,A11) -> 89 | K11: =COUNTIF('Open Decisions Master'!$A$5:$A$500,A11) -> 11 | L11: Imported
A12: v0.8 | B12: Acts and Pauline Letters | C12: Bible_Journey_Canon_Map_v0_8_Acts_Pauline_Letters.xlsx | D12: Acts and 13 Pauline letters | E12: Canon Coverage | F12: Acts narrative + epistolary placements | G12: Acts–letters profiles, prison letters, pastorals, Galatians decision | H12: =COUNTIF('Master CRS Ledger'!$A$5:$A$1000,A12) -> 40 | I12: =COUNTIF('Master Reading Blocks'!$A$5:$A$1500,A12) -> 40 | J12: =COUNTIF('Master Chapter Coverage'!$G$5:$G$2000,A12) -> 115 | K12: =COUNTIF('Open Decisions Master'!$A$5:$A$500,A12) -> 9 | L12: Imported
A13: v0.9 | B13: General Letters and Revelation | C13: Bible_Journey_Canon_Map_v0_9_General_Letters_Revelation.xlsx | D13: Hebrews, General Letters, Revelation | E13: Canon Coverage | F13: Canonical fallback and apocalyptic literary flow | G13: General-letter chronology disclosure and Revelation interpretation policy | H13: =COUNTIF('Master CRS Ledger'!$A$5:$A$1000,A13) -> 25 | I13: =COUNTIF('Master Reading Blocks'!$A$5:$A$1500,A13) -> 25 | J13: =COUNTIF('Master Chapter Coverage'!$G$5:$G$2000,A13) -> 56 | K13: =COUNTIF('Open Decisions Master'!$A$5:$A$500,A13) -> 9 | L13: Imported

Sheet Master CRS Ledger
A1: MASTER CRS LEDGER
A2: Normalized CRS inventory from Canon Maps v0.1–v0.9. Source-map order is preserved; this is not yet the final user-facing global stream order.
A4: Map Version | B4: Source Workbook | C4: Local CRS ID | D4: Local Order | E4: Map Sequence | F4: Scope / Book | G4: Era / Window | H4: Section / Act / Anchor | I4: Reading Set Title | J4: Primary / Required Scripture | K4: Event Confidence | L4: Placement Confidence | M4: Integration / Disposition | N4: Complete Reading Rule | O4: Narrative Flow Rule | P4: Compare / Group | Q4: Journey Link / Tags | R4: Cross-Map Anchor | S4: Source Keys | T4: Research Owner | U4: QA / Review Status | V4: Open Decision Flag | W4: Editorial Note
A5: v0.1 | B5: Bible_Journey_Canon_Map_v0_1_Genesis_to_2Samuel.xlsx | C5: CRS-GEN-001 | D5: 10 | E5: 1 | F5: Genesis | G5: Primeval History | H5: Origins | I5: Creation, garden, and fall | J5: Genesis 1-3 | K5: High | L5: High | N5: Read the assigned main-spine block in full. | O5: Read primary block; continue to next chronological set. | P5: No | Q5: Creation & Covenant | S5: SRC-TEXT-TORAH; SRC-TORAH-OVERVIEW | T5: Editorial | U5: Needs Review | V5: Draft | W5: Chapter-level v0.1 grouping. Future verse-level mapping can split Genesis 2:1-3 from 2:4 onward.
A6: v0.1 | B6: Bible_Journey_Canon_Map_v0_1_Genesis_to_2Samuel.xlsx | C6: CRS-GEN-002 | D6: 20 | E6: 1 | F6: Genesis | G6: Primeval History | H6: Origins | I6: Cain, Seth, and the pre-flood line | J6: Genesis 4-5 | K6: High | L6: High | N6: Read the assigned main-spine block in full. | O6: Read primary block; continue to next chronological set. | P6: No | Q6: Creation & Covenant | S6: SRC-TEXT-TORAH; SRC-TORAH-OVERVIEW | T6: Editorial | U6: Needs Review | V6: Draft
A7: v0.1 | B7: Bible_Journey_Canon_Map_v0_1_Genesis_to_2Samuel.xlsx | C7: CRS-GEN-003 | D7: 30 | E7: 1 | F7: Genesis | G7: Primeval History | H7: Flood | I7: The flood and Noahic covenant | J7: Genesis 6-9 | K7: High | L7: High | N7: Read the assigned main-spine block in full. | O7: Read primary block; continue to next chronological set. | P7: No | Q7: Creation & Covenant | S7: SRC-TEXT-TORAH; SRC-TORAH-OVERVIEW | T7: Editorial | U7: Needs Review | V7: Draft
A8: v0.1 | B8: Bible_Journey_Canon_Map_v0_1_Genesis_to_2Samuel.xlsx | C8: CRS-GEN-004 | D8: 40 | E8: 1 | F8: Genesis | G8: Primeval History | H8: Nations and Babel | I8: Nations and the tower of Babel | J8: Genesis 10-11 | K8: High | L8: High | N8: Read the assigned main-spine block in full. | O8: Read primary block; continue to next chronological set. | P8: No | Q8: Creation & Covenant | S8: SRC-TEXT-TORAH; SRC-TORAH-OVERVIEW | T8: Editorial | U8: Needs Review | V8: Draft
A9: v0.1 | B9: Bible_Journey_Canon_Map_v0_1_Genesis_to_2Samuel.xlsx | C9: CRS-GEN-005 | D9: 50 | E9: 1 | F9: Genesis | G9: Patriarchs | H9: Abraham | I9: Abram's call, separation, and rescue of Lot | J9: Genesis 12-14 | K9: High | L9: High | N9: Read the assigned main-spine block in full. | O9: Read primary block; continue to next chronological set. | P9: No | Q9: Abraham | S9: SRC-TEXT-TORAH; SRC-TORAH-OVERVIEW | T9: Editorial | U9: Needs Review | V9: Draft
A10: v0.1 | B10: Bible_Journey_Canon_Map_v0_1_Genesis_to_2Samuel.xlsx | C10: CRS-GEN-006 | D10: 60 | E10: 1 | F10: Genesis | G10: Patriarchs | H10: Abraham | I10: Covenant, Hagar, and the promised son | J10: Genesis 15-17 | K10: High | L10: High | N10: Read the assigned main-spine block in full. | O10: Read primary block; continue to next chronological set. | P10: No | Q10: Abraham | S10: SRC-TEXT-TORAH; SRC-TORAH-OVERVIEW | T10: Editorial | U10: Needs Review | V10: Draft
A11: v0.1 | B11: Bible_Journey_Canon_Map_v0_1_Genesis_to_2Samuel.xlsx | C11: CRS-GEN-007 | D11: 70 | E11: 1 | F11: Genesis | G11: Patriarchs | H11: Abraham | I11: Sodom, Gomorrah, and Lot's escape | J11: Genesis 18-19 | K11: High | L11: High | N11: Read the assigned main-spine block in full. | O11: Read primary block; continue to next chronological set. | P11: No | Q11: Abraham | S11: SRC-TEXT-TORAH; SRC-TORAH-OVERVIEW | T11: Editorial | U11: Needs Review | V11: Draft
A12: v0.1 | B12: Bible_Journey_Canon_Map_v0_1_Genesis_to_2Samuel.xlsx | C12: CRS-GEN-008 | D12: 80 | E12: 1 | F12: Genesis | G12: Patriarchs | H12: Abraham | I12: Abimelech, Isaac's birth, and Moriah | J12: Genesis 20-22 | K12: High | L12: High | N12: Read the assigned main-spine block in full. | O12: Read primary block; continue to next chronological set. | P12: No | Q12: Abraham | S12: SRC-TEXT-TORAH; SRC-TORAH-OVERVIEW | T12: Editorial | U12: Needs Review | V12: Draft
A13: v0.1 | B13: Bible_Journey_Canon_Map_v0_1_Genesis_to_2Samuel.xlsx | C13: CRS-GEN-009 | D13: 90 | E13: 1 | F13: Genesis | G13: Patriarchs | H13: Transition to Isaac | I13: Sarah's burial, Rebekah, and Abraham's final years | J13: Genesis 23-25 | K13: High | L13: High | N13: Read the assigned main-spine block in full. | O13: Read primary block; continue to next chronological set. | P13: No | Q13: Abraham; Isaac | S13: SRC-TEXT-TORAH; SRC-TORAH-OVERVIEW | T13: Editorial | U13: Needs Review | V13: Draft
A14: v0.1 | B14: Bible_Journey_Canon_Map_v0_1_Genesis_to_2Samuel.xlsx | C14: CRS-GEN-010 | D14: 100 | E14: 1 | F14: Genesis | G14: Patriarchs | H14: Jacob | I14: Isaac's household and Jacob's departure | J14: Genesis 26-28 | K14: High | L14: High | N14: Read the assigned main-spine block in full. | O14: Read primary block; continue to next chronological set. | P14: No | Q14: Jacob | S14: SRC-TEXT-TORAH; SRC-TORAH-OVERVIEW | T14: Editorial | U14: Needs Review | V14: Draft
A15: v0.1 | B15: Bible_Journey_Canon_Map_v0_1_Genesis_to_2Samuel.xlsx | C15: CRS-GEN-011 | D15: 110 | E15: 1 | F15: Genesis | G15: Patriarchs | H15: Jacob | I15: Jacob in Haran | J15: Genesis 29-31 | K15: High | L15: High | N15: Read the assigned main-spine block in full. | O15: Read primary block; continue to next chronological set. | P15: No | Q15: Jacob | S15: SRC-TEXT-TORAH; SRC-TORAH-OVERVIEW | T15: Editorial | U15: Needs Review | V15: Draft
A16: v0.1 | B16: Bible_Journey_Canon_Map_v0_1_Genesis_to_2Samuel.xlsx | C16: CRS-GEN-012 | D16: 120 | E16: 1 | F16: Genesis | G16: Patriarchs | H16: Jacob | I16: Jacob returns and is reconciled with Esau | J16: Genesis 32-33 | K16: High | L16: High | N16: Read the assigned main-spine block in full. | O16: Read primary block; continue to next chronological set. | P16: No | Q16: Jacob | S16: SRC-TEXT-TORAH; SRC-TORAH-OVERVIEW | T16: Editorial | U16: Needs Review | V16: Draft
A17: v0.1 | B17: Bible_Journey_Canon_Map_v0_1_Genesis_to_2Samuel.xlsx | C17: CRS-GEN-013 | D17: 130 | E17: 1 | F17: Genesis | G17: Patriarchs | H17: Jacob | I17: Dinah, Bethel, and Esau's line | J17: Genesis 34-36 | K17: High | L17: High | N17: Read the assigned main-spine block in full. | O17: Read primary block; continue to next chronological set. | P17: No | Q17: Jacob | S17: SRC-TEXT-TORAH; SRC-TORAH-OVERVIEW | T17: Editorial | U17: Needs Review | V17: Draft
... A66: v0.1 | B66: Bible_Journey_Canon_Map_v0_1_Genesis_to_2Samuel.xlsx | C66: CRS-JOS-006 | D66: 620 | E66: 1 | F66: Joshua | G66: Conquest & Settlement | H66: Northern campaign | I66: Northern campaign and conquest summary | J66: Joshua 11-12 | K66: High | L66: High | N66: Read the assigned main-spine block in full. | O66: Read primary block; continue to next chronological set. | P66: No | Q66: Conquest | S66: SRC-TEXT-JOSHUA; SRC-DET-HISTORY | T66: Editorial | U66: Needs Review | V66: Draft
A67: v0.1 | B67: Bible_Journey_Canon_Map_v0_1_Genesis_to_2Samuel.xlsx | C67: CRS-JOS-007 | D67: 630 | E67: 1 | F67: Joshua | G67: Conquest & Settlement | H67: Allotment | I67: Tribal allotments | J67: Joshua 13-19 | K67: High | L67: High | N67: Read the assigned main-spine block in full. | O67: Read primary block; continue to next chronological set. | P67: No | Q67: Conquest | S67: SRC-TEXT-JOSHUA; SRC-DET-HISTORY | T67: Editorial | U67: Needs Review | V67: Draft | W67: Reading section rather than a single battlefield event; retain maps and territory layers as optional study context.
A68: v0.1 | B68: Bible_Journey_Canon_Map_v0_1_Genesis_to_2Samuel.xlsx | C68: CRS-JOS-008 | D68: 640 | E68: 1 | F68: Joshua | G68: Conquest & Settlement | H68: Settlement | I68: Cities of refuge, Levites, and the eastern altar | J68: Joshua 20-22 | K68: High | L68: High | N68: Read the assigned main-spine block in full. | O68: Read primary block; continue to next chronological set. | P68: No | Q68: Conquest | S68: SRC-TEXT-JOSHUA; SRC-DET-HISTORY | T68: Editorial | U68: Needs Review | V68: Draft
A69: v0.1 | B69: Bible_Journey_Canon_Map_v0_1_Genesis_to_2Samuel.xlsx | C69: CRS-JOS-009 | D69: 650 | E69: 1 | F69: Joshua | G69: Conquest & Settlement | H69: Covenant | I69: Joshua's farewell and covenant renewal | J69: Joshua 23-24 | K69: High | L69: High | N69: Read the assigned main-spine block in full. | O69: Read primary block; continue to next chronological set. | P69: No | Q69: Conquest | S69: SRC-TEXT-JOSHUA; SRC-DET-HISTORY | T69: Editorial | U69: Needs Review | V69: Draft
A70: v0.1 | B70: Bible_Journey_Canon_Map_v0_1_Genesis_to_2Samuel.xlsx | C70: CRS-JDG-001 | D70: 660 | E70: 1 | F70: Judges | G70: Judges | H70: Opening cycles | I70: Incomplete conquest and the pattern of the judges | J70: Judges 1-3 | K70: High | L70: High | N70: Read the assigned main-spine block in full. | O70: Read primary block; continue to next chronological set. | P70: No | Q70: Judges | S70: SRC-TEXT-JUDGES; SRC-DET-HISTORY | T70: Editorial | U70: Needs Review | V70: Draft | W70: Chapter 3 contains both cycle introduction and early judges. Keep chapter-level v0.1 grouping; verse-level segmentation is a later refinement.
A71: v0.1 | B71: Bible_Journey_Canon_Map_v0_1_Genesis_to_2Samuel.xlsx | C71: CRS-JDG-002 | D71: 670 | E71: 1 | F71: Judges | G71: Judges | H71: Deborah and Barak | I71: Deborah, Barak, and the song of deliverance | J71: Judges 4-5 | K71: High | L71: High | N71: Read the assigned main-spine block in full. | O71: Read primary block; continue to next chronological set. | P71: No | Q71: Judges | S71: SRC-TEXT-JUDGES; SRC-DET-HISTORY | T71: Editorial | U71: Needs Review | V71: Draft
A72: v0.1 | B72: Bible_Journey_Canon_Map_v0_1_Genesis_to_2Samuel.xlsx | C72: CRS-JDG-003 | D72: 680 | E72: 1 | F72: Judges | G72: Judges | H72: Gideon | I72: Gideon's calling, victory, and legacy | J72: Judges 6-8 | K72: High | L72: High | N72: Read the assigned main-spine block in full. | O72: Read primary block; continue to next chronological set. | P72: No | Q72: Judges | S72: SRC-TEXT-JUDGES; SRC-DET-HISTORY | T72: Editorial | U72: Needs Review | V72: Draft
A73: v0.1 | B73: Bible_Journey_Canon_Map_v0_1_Genesis_to_2Samuel.xlsx | C73: CRS-JDG-004 | D73: 690 | E73: 1 | F73: Judges | G73: Judges | H73: Abimelech | I73: Abimelech's rise and fall | J73: Judges 9 | K73: High | L73: High | N73: Read the assigned main-spine block in full. | O73: Read primary block; continue to next chronological set. | P73: No | Q73: Judges | S73: SRC-TEXT-JUDGES; SRC-DET-HISTORY | T73: Editorial | U73: Needs Review | V73: Draft
A74: v0.1 | B74: Bible_Journey_Canon_Map_v0_1_Genesis_to_2Samuel.xlsx | C74: CRS-JDG-005 | D74: 700 | E74: 1 | F74: Judges | G74: Judges | H74: Eastern judges | I74: Jephthah and the eastern judges | J74: Judges 10-12 | K74: High | L74: High | N74: Read the assigned main-spine block in full. | O74: Read primary block; continue to next chronological set. | P74: No | Q74: Judges | S74: SRC-TEXT-JUDGES; SRC-DET-HISTORY | T74: Editorial | U74: Needs Review | V74: Draft
A75: v0.1 | B75: Bible_Journey_Canon_Map_v0_1_Genesis_to_2Samuel.xlsx | C75: CRS-JDG-006 | D75: 710 | E75: 1 | F75: Judges | G75: Judges | H75: Samson | I75: Samson's birth, conflicts, and death | J75: Judges 13-16 | K75: High | L75: High | N75: Read the assigned main-spine block in full. | O75: Read primary block; continue to next chronological set. | P75: No | Q75: Judges | S75: SRC-TEXT-JUDGES; SRC-DET-HISTORY | T75: Editorial | U75: Needs Review | V75: Draft
A76: v0.1 | B76: Bible_Journey_Canon_Map_v0_1_Genesis_to_2Samuel.xlsx | C76: CRS-JDG-007 | D76: 720 | E76: 1 | F76: Judges | G76: Judges | H76: Tribal disorder | I76: Micah, the Levite, and the tribe of Dan | J76: Judges 17-18 | K76: High | L76: Probable | N76: Read the assigned main-spine block in full. | O76: Read primary block; continue to next chronological set. | P76: No | Q76: Judges | S76: SRC-TEXT-JUDGES; SRC-DET-HISTORY | T76: Editorial | U76: Needs Review | V76: Draft | W76: These chapters are not necessarily placed in strict historical sequence by the narrative. V0.1 keeps canonical order and flags the section as an editorial placement.
A77: v0.1 | B77: Bible_Journey_Canon_Map_v0_1_Genesis_to_2Samuel.xlsx | C77: CRS-JDG-008 | D77: 730 | E77: 1 | F77: Judges | G77: Judges | H77: Tribal disorder | I77: Gibeah and the civil war | J77: Judges 19-21 | K77: High | L77: Probable | N77: Read the assigned main-spine block in full. | O77: Read primary block; continue to next chronological set. | P77: No | Q77: Judges | S77: SRC-TEXT-JUDGES; SRC-DET-HISTORY | T77: Editorial | U77: Needs Review | V77: Draft | W77: These chapters are not necessarily placed in strict historical sequence by the narrative. V0.1 keeps canonical order and flags the section as an editorial placement.
A78: v0.1 | B78: Bible_Journey_Canon_Map_v0_1_Genesis_to_2Samuel.xlsx | C78: CRS-RUT-001 | D78: 740 | E78: 1 | F78: Ruth | G78: Judges | H78: Ruth | I78: Ruth, Naomi, Boaz, and the Davidic line | J78: Ruth 1-4 | K78: High | L78: Probable | N78: Read the assigned main-spine block in full. | O78: Read primary block; continue to next chronological set. | P78: No | Q78: Ruth; Davidic Line | S78: SRC-TEXT-RUTH | T78: Editorial | U78: Needs Review | V78: Draft | W78: The book is set 'in the days when the judges ruled'; its precise placement within the judges period is not stated.
A79: v0.1 | B79: Bible_Journey_Canon_Map_v0_1_Genesis_to_2Samuel.xlsx | C79: CRS-1SA-001 | D79: 750 | E79: 1 | F79: 1 Samuel | G79: Rise of the Monarchy | H79: Samuel | I79: Samuel's birth, dedication, and call | J79: 1 Samuel 1-3 | K79: High | L79: High | N79: Read the assigned main-spine block in full. | O79: Read primary block; continue to next chronological set. | P79: No | Q79: Samuel; Rise of the Monarchy | S79: SRC-TEXT-1SAM; SRC-SAMUEL-OVERVIEW; SRC-DAVID-OVERVIEW | T79: Editorial | U79: Needs Review | V79: Draft
A80: v0.1 | B80: Bible_Journey_Canon_Map_v0_1_Genesis_to_2Samuel.xlsx | C80: CRS-1SA-002 | D80: 760 | E80: 1 | F80: 1 Samuel | G80: Rise of the Monarchy | H80: Ark narrative | I80: The ark captured, returned, and restored | J80: 1 Samuel 4-7 | K80: High | L80: High | N80: Read the assigned main-spine block in full. | O80: Read primary block; continue to next chronological set. | P80: No | Q80: Samuel; Rise of the Monarchy | S80: SRC-TEXT-1SAM; SRC-SAMUEL-OVERVIEW; SRC-DAVID-OVERVIEW | T80: Editorial | U80: Needs Review | V80: Draft
A81: v0.1 | B81: Bible_Journey_Canon_Map_v0_1_Genesis_to_2Samuel.xlsx | C81: CRS-1SA-003 | D81: 770 | E81: 1 | F81: 1 Samuel | G81: Rise of the Monarchy | H81: Saul | I81: Israel asks for a king and Saul is chosen | J81: 1 Samuel 8-10 | K81: High | L81: High | N81: Read the assigned main-spine block in full. | O81: Read primary block; continue to next chronological set. | P81: No | Q81: Saul; Rise of the Monarchy | S81: SRC-TEXT-1SAM; SRC-SAMUEL-OVERVIEW; SRC-DAVID-OVERVIEW | T81: Editorial | U81: Needs Review | V81: Draft
A82: v0.1 | B82: Bible_Journey_Canon_Map_v0_1_Genesis_to_2Samuel.xlsx | C82: CRS-1SA-004 | D82: 780 | E82: 1 | F82: 1 Samuel | G82: Rise of the Monarchy | H82: Saul | I82: Saul delivers Jabesh and the kingdom is renewed | J82: 1 Samuel 11-12 | K82: High | L82: High | N82: Read the assigned main-spine block in full. | O82: Read primary block; continue to next chronological set. | P82: No | Q82: Saul; Rise of the Monarchy | S82: SRC-TEXT-1SAM; SRC-SAMUEL-OVERVIEW; SRC-DAVID-OVERVIEW | T82: Editorial | U82: Needs Review | V82: Draft
A83: v0.1 | B83: Bible_Journey_Canon_Map_v0_1_Genesis_to_2Samuel.xlsx | C83: CRS-1SA-005 | D83: 790 | E83: 1 | F83: 1 Samuel | G83: Rise of the Monarchy | H83: Saul | I83: Saul's early reign and rejection | J83: 1 Samuel 13-15 | K83: High | L83: High | N83: Read the assigned main-spine block in full. | O83: Read primary block; continue to next chronological set. | P83: No | Q83: Saul; Rise of the Monarchy | S83: SRC-TEXT-1SAM; SRC-SAMUEL-OVERVIEW; SRC-DAVID-OVERVIEW | T83: Editorial | U83: Needs Review | V83: Draft
A84: v0.1 | B84: Bible_Journey_Canon_Map_v0_1_Genesis_to_2Samuel.xlsx | C84: CRS-1SA-006 | D84: 800 | E84: 1 | F84: 1 Samuel | G84: Rise of the Monarchy | H84: David / Act I: The Chosen One | I84: David anointed and enters Saul's service | J84: 1 Samuel 16 | K84: High | L84: Probable | N84: Read the assigned main-spine block in full. | O84: Read primary block; continue to next chronological set. | P84: No | Q84: The Life of David; Saul | S84: SRC-TEXT-1SAM; SRC-SAMUEL-OVERVIEW; SRC-DAVID-OVERVIEW | T84: Editorial | U84: Needs Review | V84: Draft | W84: V0.1 follows the canonical sequence. The relation between David's early court service and the Goliath narrative is a documented editorial / source-critical discussion to be tracked separately.
A85: v0.1 | B85: Bible_Journey_Canon_Map_v0_1_Genesis_to_2Samuel.xlsx | C85: CRS-1SA-007 | D85: 810 | E85: 1 | F85: 1 Samuel | G85: Rise of the Monarchy | H85: David / Act I: The Chosen One | I85: David and Goliath | J85: 1 Samuel 17 | K85: High | L85: Probable | N85: Read the assigned main-spine block in full. | O85: Read primary block; continue to next chronological set. | P85: No | Q85: The Life of David | S85: SRC-TEXT-1SAM; SRC-SAMUEL-OVERVIEW; SRC-DAVID-OVERVIEW | T85: Editorial | U85: Needs Review | V85: Draft
A86: v0.1 | B86: Bible_Journey_Canon_Map_v0_1_Genesis_to_2Samuel.xlsx | C86: CRS-1SA-008 | D86: 820 | E86: 1 | F86: 1 Samuel | G86: Rise of the Monarchy | H86: David / Act I: The Chosen One | I86: David in Saul's court and covenant with Jonathan | J86: 1 Samuel 18 | K86: High | L86: Probable | N86: Read the assigned main-spine block in full. | O86: Read primary block; continue to next chronological set. | P86: No | Q86: The Life of David; Jonathan | S86: SRC-TEXT-1SAM; SRC-SAMUEL-OVERVIEW; SRC-DAVID-OVERVIEW | T86: Editorial | U86: Needs Review | V86: Draft
A87: v0.1 | B87: Bible_Journey_Canon_Map_v0_1_Genesis_to_2Samuel.xlsx | C87: CRS-1SA-009 | D87: 830 | E87: 1 | F87: 1 Samuel | G87: Rise of the Monarchy | H87: David / Act II: The Fugitive | I87: David escapes Saul's first pursuit | J87: 1 Samuel 19 | K87: High | L87: Probable | N87: Read all assigned blocks; external links marked required in Full Stream must be completed before full-event completion. | O87: Read primary block; clearly surface linked accounts as pending, never auto-complete. | P87: No | Q87: The Life of David | S87: SRC-TEXT-1SAM; SRC-SAMUEL-OVERVIEW; SRC-DAVID-OVERVIEW | T87: Editorial | U87: Needs Review | V87: Draft
A88: v0.1 | B88: Bible_Journey_Canon_Map_v0_1_Genesis_to_2Samuel.xlsx | C88: CRS-1SA-010 | D88: 840 | E88: 1 | F88: 1 Samuel | G88: Rise of the Monarchy | H88: David / Act II: The Fugitive | I88: David and Jonathan's covenant renewed | J88: 1 Samuel 20 | K88: High | L88: Probable | N88: Read the assigned main-spine block in full. | O88: Read primary block; continue to next chronological set. | P88: No | Q88: The Life of David; Jonathan | S88: SRC-TEXT-1SAM; SRC-SAMUEL-OVERVIEW; SRC-DAVID-OVERVIEW | T88: Editorial | U88: Needs Review | V88: Draft
A89: v0.1 | B89: Bible_Journey_Canon_Map_v0_1_Genesis_to_2Samuel.xlsx | C89: CRS-1SA-011 | D89: 850 | E89: 1 | F89: 1 Samuel | G89: Rise of the Monarchy | H89: David / Act II: The Fugitive | I89: David at Nob and Gath | J89: 1 Samuel 21 | K89: High | L89: Probable | N89: Read all assigned blocks; external links marked required in Full Stream must be completed before full-event completion. | O89: Read primary block; clearly surface linked accounts as pending, never auto-complete. | P89: No | Q89: The Life of David | S89: SRC-TEXT-1SAM; SRC-SAMUEL-OVERVIEW; SRC-DAVID-OVERVIEW | T89: Editorial | U89: Needs Review | V89: Draft
...

Sheet Master Reading Blocks
A1: MASTER READING BLOCKS
A2: Normalized inventory of intact canonical blocks. These are future passage-level units for Reader, progress logic, and Compare Accounts.
A4: Map Version | B4: Source Workbook | C4: Local Block ID | D4: Parent CRS ID | E4: Display / Block Order | F4: Book | G4: Passage / Reference | H4: Block Role | I4: In Scope | J4: Required in Full Stream | K4: Narrative Flow Default | L4: Event / Setting Confidence | M4: Placement Confidence | N4: Integration / Anchor / Exception | O4: Target CRS / Compare Group | P4: End-User Label | Q4: Source Keys | R4: QA / Review Status | S4: Why It Appears Here / Notes
A5: v0.1 | B5: Bible_Journey_Canon_Map_v0_1_Genesis_to_2Samuel.xlsx | C5: BLK-GEN-001-01 | D5: CRS-GEN-001 | E5: 1 | F5: Genesis | G5: 1-3 | H5: Primary Account | I5: Yes | J5: Yes | K5: Yes | L5: High | M5: High | N5: Genesis | P5: Primary account | Q5: SRC-TEXT-TORAH; SRC-TORAH-OVERVIEW | R5: Needs Review | S5: Canonical spine reading block for Creation, garden, and fall.
A6: v0.1 | B6: Bible_Journey_Canon_Map_v0_1_Genesis_to_2Samuel.xlsx | C6: BLK-GEN-002-01 | D6: CRS-GEN-002 | E6: 1 | F6: Genesis | G6: 4-5 | H6: Primary Account | I6: Yes | J6: Yes | K6: Yes | L6: High | M6: High | N6: Genesis | P6: Primary account | Q6: SRC-TEXT-TORAH; SRC-TORAH-OVERVIEW | R6: Needs Review | S6: Canonical spine reading block for Cain, Seth, and the pre-flood line.
A7: v0.1 | B7: Bible_Journey_Canon_Map_v0_1_Genesis_to_2Samuel.xlsx | C7: BLK-GEN-003-01 | D7: CRS-GEN-003 | E7: 1 | F7: Genesis | G7: 6-9 | H7: Primary Account | I7: Yes | J7: Yes | K7: Yes | L7: High | M7: High | N7: Genesis | P7: Primary account | Q7: SRC-TEXT-TORAH; SRC-TORAH-OVERVIEW | R7: Needs Review | S7: Canonical spine reading block for The flood and Noahic covenant.
A8: v0.1 | B8: Bible_Journey_Canon_Map_v0_1_Genesis_to_2Samuel.xlsx | C8: BLK-GEN-004-01 | D8: CRS-GEN-004 | E8: 1 | F8: Genesis | G8: 10-11 | H8: Primary Account | I8: Yes | J8: Yes | K8: Yes | L8: High | M8: High | N8: Genesis | P8: Primary account | Q8: SRC-TEXT-TORAH; SRC-TORAH-OVERVIEW | R8: Needs Review | S8: Canonical spine reading block for Nations and the tower of Babel.
A9: v0.1 | B9: Bible_Journey_Canon_Map_v0_1_Genesis_to_2Samuel.xlsx | C9: BLK-GEN-005-01 | D9: CRS-GEN-005 | E9: 1 | F9: Genesis | G9: 12-14 | H9: Primary Account | I9: Yes | J9: Yes | K9: Yes | L9: High | M9: High | N9: Genesis | P9: Primary account | Q9: SRC-TEXT-TORAH; SRC-TORAH-OVERVIEW | R9: Needs Review | S9: Canonical spine reading block for Abram's call, separation, and rescue of Lot.
A10: v0.1 | B10: Bible_Journey_Canon_Map_v0_1_Genesis_to_2Samuel.xlsx | C10: BLK-GEN-006-01 | D10: CRS-GEN-006 | E10: 1 | F10: Genesis | G10: 15-17 | H10: Primary Account | I10: Yes | J10: Yes | K10: Yes | L10: High | M10: High | N10: Genesis | P10: Primary account | Q10: SRC-TEXT-TORAH; SRC-TORAH-OVERVIEW | R10: Needs Review | S10: Canonical spine reading block for Covenant, Hagar, and the promised son.
A11: v0.1 | B11: Bible_Journey_Canon_Map_v0_1_Genesis_to_2Samuel.xlsx | C11: BLK-GEN-007-01 | D11: CRS-GEN-007 | E11: 1 | F11: Genesis | G11: 18-19 | H11: Primary Account | I11: Yes | J11: Yes | K11: Yes | L11: High | M11: High | N11: Genesis | P11: Primary account | Q11: SRC-TEXT-TORAH; SRC-TORAH-OVERVIEW | R11: Needs Review | S11: Canonical spine reading block for Sodom, Gomorrah, and Lot's escape.
A12: v0.1 | B12: Bible_Journey_Canon_Map_v0_1_Genesis_to_2Samuel.xlsx | C12: BLK-GEN-008-01 | D12: CRS-GEN-008 | E12: 1 | F12: Genesis | G12: 20-22 | H12: Primary Account | I12: Yes | J12: Yes | K12: Yes | L12: High | M12: High | N12: Genesis | P12: Primary account | Q12: SRC-TEXT-TORAH; SRC-TORAH-OVERVIEW | R12: Needs Review | S12: Canonical spine reading block for Abimelech, Isaac's birth, and Moriah.
A13: v0.1 | B13: Bible_Journey_Canon_Map_v0_1_Genesis_to_2Samuel.xlsx | C13: BLK-GEN-009-01 | D13: CRS-GEN-009 | E13: 1 | F13: Genesis | G13: 23-25 | H13: Primary Account | I13: Yes | J13: Yes | K13: Yes | L13: High | M13: High | N13: Genesis | P13: Primary account | Q13: SRC-TEXT-TORAH; SRC-TORAH-OVERVIEW | R13: Needs Review | S13: Canonical spine reading block for Sarah's burial, Rebekah, and Abraham's final years.
A14: v0.1 | B14: Bible_Journey_Canon_Map_v0_1_Genesis_to_2Samuel.xlsx | C14: BLK-GEN-010-01 | D14: CRS-GEN-010 | E14: 1 | F14: Genesis | G14: 26-28 | H14: Primary Account | I14: Yes | J14: Yes | K14: Yes | L14: High | M14: High | N14: Genesis | P14: Primary account | Q14: SRC-TEXT-TORAH; SRC-TORAH-OVERVIEW | R14: Needs Review | S14: Canonical spine reading block for Isaac's household and Jacob's departure.
A15: v0.1 | B15: Bible_Journey_Canon_Map_v0_1_Genesis_to_2Samuel.xlsx | C15: BLK-GEN-011-01 | D15: CRS-GEN-011 | E15: 1 | F15: Genesis | G15: 29-31 | H15: Primary Account | I15: Yes | J15: Yes | K15: Yes | L15: High | M15: High | N15: Genesis | P15: Primary account | Q15: SRC-TEXT-TORAH; SRC-TORAH-OVERVIEW | R15: Needs Review | S15: Canonical spine reading block for Jacob in Haran.
A16: v0.1 | B16: Bible_Journey_Canon_Map_v0_1_Genesis_to_2Samuel.xlsx | C16: BLK-GEN-012-01 | D16: CRS-GEN-012 | E16: 1 | F16: Genesis | G16: 32-33 | H16: Primary Account | I16: Yes | J16: Yes | K16: Yes | L16: High | M16: High | N16: Genesis | P16: Primary account | Q16: SRC-TEXT-TORAH; SRC-TORAH-OVERVIEW | R16: Needs Review | S16: Canonical spine reading block for Jacob returns and is reconciled with Esau.
... A139: v0.1 | B139: Bible_Journey_Canon_Map_v0_1_Genesis_to_2Samuel.xlsx | C139: BLK-2SA-021-03 | D139: CRS-2SA-021 | E139: 3 | F139: 1 Chronicles | G139: 22:1 | H139: Supplementary Reading | I139: No | J139: Yes | K139: No | L139: High | M139: Debated | N139: 1 Chronicles | P139: Temple-site continuation | Q139: SRC-TEXT-1CHR; SRC-CHRONICLES-OVERVIEW | R139: Pending | S139: This verse connects the altar site to David's preparation for the temple. It is a continuation, not a duplicate.
A140: v0.2 | B140: Bible_Journey_Canon_Map_v0_2_Chronicles_Psalms_Job_1Kings.xlsx | C140: BLK-1CH-007-01 | D140: CRS-1CH-007 | E140: 1 | F140: 1 Chronicles | G140: 10 | H140: Parallel Account | I140: Yes | J140: Yes | K140: No | L140: High | M140: High | N140: Attach to v0.1 event | O140: CRS-1SA-021 | P140: Parallel Account | Q140: SRC-TEXT-1CHR; SRC-CHRONICLES-OVERVIEW; SRC-CHRONICLES-BP | R140: Needs Review | S140: Canonical-scope block for Saul dies at Gilboa: Chronicles account.
A141: v0.2 | B141: Bible_Journey_Canon_Map_v0_2_Chronicles_Psalms_Job_1Kings.xlsx | C141: BLK-1CH-009-01 | D141: CRS-1CH-009 | E141: 1 | F141: 1 Chronicles | G141: 12 | H141: Supplementary Reading | I141: Yes | J141: Yes | K141: No | L141: High | M141: Probable | N141: Contextual composite / multi-event window | O141: CRS-1SA-011–020; CRS-2SA-001 | P141: Supplementary Reading | Q141: SRC-TEXT-1CHR; SRC-CHRONICLES-OVERVIEW; SRC-CHRONICLES-BP | R141: Needs Review | S141: Canonical-scope block for David's supporters gather to him.
A142: v0.2 | B142: Bible_Journey_Canon_Map_v0_2_Chronicles_Psalms_Job_1Kings.xlsx | C142: BLK-1CH-008-01 | D142: CRS-1CH-008 | E142: 1 | F142: 1 Chronicles | G142: 11 | H142: Parallel Account | I142: Yes | J142: Yes | K142: No | L142: High | M142: High | N142: Attach to v0.1 event | O142: CRS-2SA-003 | P142: Parallel Account | Q142: SRC-TEXT-1CHR; SRC-CHRONICLES-OVERVIEW; SRC-CHRONICLES-BP | R142: Needs Review | S142: Canonical-scope block for David becomes king and takes Jerusalem: Chronicles account.
A143: v0.2 | B143: Bible_Journey_Canon_Map_v0_2_Chronicles_Psalms_Job_1Kings.xlsx | C143: BLK-1CH-011-01 | D143: CRS-1CH-011 | E143: 1 | F143: 1 Chronicles | G143: 14 | H143: Parallel Account | I143: Yes | J143: Yes | K143: No | L143: High | M143: High | N143: Attach to v0.1 event | O143: CRS-2SA-003 | P143: Parallel Account | Q143: SRC-TEXT-1CHR; SRC-CHRONICLES-OVERVIEW; SRC-CHRONICLES-BP | R143: Needs Review | S143: Canonical-scope block for David's palace and wars with the Philistines: Chronicles account.
A144: v0.2 | B144: Bible_Journey_Canon_Map_v0_2_Chronicles_Psalms_Job_1Kings.xlsx | C144: BLK-1CH-010-01 | D144: CRS-1CH-010 | E144: 1 | F144: 1 Chronicles | G144: 13 | H144: Parallel Account | I144: Yes | J144: Yes | K144: No | L144: High | M144: High | N144: Attach to v0.1 event | O144: CRS-2SA-004 | P144: Parallel Account | Q144: SRC-TEXT-1CHR; SRC-CHRONICLES-OVERVIEW; SRC-CHRONICLES-BP | R144: Needs Review | S144: Canonical-scope block for The ark's first journey and Uzzah's death: Chronicles account.
A145: v0.2 | B145: Bible_Journey_Canon_Map_v0_2_Chronicles_Psalms_Job_1Kings.xlsx | C145: BLK-1CH-012-01 | D145: CRS-1CH-012 | E145: 1 | F145: 1 Chronicles | G145: 15-16 | H145: Complementary Account | I145: Yes | J145: Yes | K145: No | L145: High | M145: High | N145: Attach to v0.1 event | O145: CRS-2SA-004 | P145: Complementary Account | Q145: SRC-TEXT-1CHR; SRC-CHRONICLES-OVERVIEW; SRC-CHRONICLES-BP | R145: Needs Review | S145: Canonical-scope block for The ark enters Jerusalem and David's liturgy.
A146: v0.2 | B146: Bible_Journey_Canon_Map_v0_2_Chronicles_Psalms_Job_1Kings.xlsx | C146: BLK-1CH-013-01 | D146: CRS-1CH-013 | E146: 1 | F146: 1 Chronicles | G146: 17 | H146: Parallel Account | I146: Yes | J146: Yes | K146: No | L146: High | M146: High | N146: Attach to v0.1 event | O146: CRS-2SA-005 | P146: Parallel Account | Q146: SRC-TEXT-1CHR; SRC-CHRONICLES-OVERVIEW; SRC-CHRONICLES-BP | R146: Needs Review | S146: Canonical-scope block for The Davidic covenant: Chronicles account.
A147: v0.2 | B147: Bible_Journey_Canon_Map_v0_2_Chronicles_Psalms_Job_1Kings.xlsx | C147: BLK-1CH-014-01 | D147: CRS-1CH-014 | E147: 1 | F147: 1 Chronicles | G147: 18 | H147: Parallel Account | I147: Yes | J147: Yes | K147: No | L147: High | M147: High | N147: Attach to v0.1 event | O147: CRS-2SA-006 | P147: Parallel Account | Q147: SRC-TEXT-1CHR; SRC-CHRONICLES-OVERVIEW; SRC-CHRONICLES-BP | R147: Needs Review | S147: Canonical-scope block for David's victories and administration: Chronicles account.
A148: v0.2 | B148: Bible_Journey_Canon_Map_v0_2_Chronicles_Psalms_Job_1Kings.xlsx | C148: BLK-1CH-015-01 | D148: CRS-1CH-015 | E148: 1 | F148: 1 Chronicles | G148: 19 | H148: Parallel Account | I148: Yes | J148: Yes | K148: No | L148: High | M148: High | N148: Attach to v0.1 event | O148: CRS-2SA-008 | P148: Parallel Account | Q148: SRC-TEXT-1CHR; SRC-CHRONICLES-OVERVIEW; SRC-CHRONICLES-BP | R148: Needs Review | S148: Canonical-scope block for War with Ammon and Aram: Chronicles account.
A149: v0.2 | B149: Bible_Journey_Canon_Map_v0_2_Chronicles_Psalms_Job_1Kings.xlsx | C149: BLK-1CH-016-01 | D149: CRS-1CH-016 | E149: 1 | F149: 1 Chronicles | G149: 20 | H149: Complementary Account | I149: Yes | J149: Yes | K149: No | L149: High | M149: Debated | N149: Contextual composite / multi-event window | O149: CRS-2SA-010; CRS-2SA-018 | P149: Complementary Account | Q149: SRC-TEXT-1CHR; SRC-CHRONICLES-OVERVIEW; SRC-CHRONICLES-BP | R149: Needs Review | S149: Canonical-scope block for Rabbah and Philistine giants: Chronicles accounts.
A150: v0.2 | B150: Bible_Journey_Canon_Map_v0_2_Chronicles_Psalms_Job_1Kings.xlsx | C150: BLK-1CH-017-01 | D150: CRS-1CH-017 | E150: 1 | F150: 1 Chronicles | G150: 21 | H150: Parallel Account | I150: Yes | J150: Yes | K150: No | L150: High | M150: Debated | N150: Attach to v0.1 event | O150: CRS-2SA-021 | P150: Parallel Account | Q150: SRC-TEXT-1CHR; SRC-CHRONICLES-OVERVIEW; SRC-CHRONICLES-BP | R150: Needs Review | S150: Canonical-scope block for David's census and altar site: Chronicles account.
A151: v0.2 | B151: Bible_Journey_Canon_Map_v0_2_Chronicles_Psalms_Job_1Kings.xlsx | C151: BLK-1CH-018-01 | D151: CRS-1CH-018 | E151: 1 | F151: 1 Chronicles | G151: 22 | H151: Primary Account | I151: Yes | J151: Yes | K151: Yes | L151: High | M151: Probable | N151: New main-spine bridge | P151: Primary account | Q151: SRC-TEXT-1CHR; SRC-CHRONICLES-OVERVIEW; SRC-CHRONICLES-BP | R151: Needs Review | S151: Canonical-scope block for David prepares for the temple.
A152: v0.2 | B152: Bible_Journey_Canon_Map_v0_2_Chronicles_Psalms_Job_1Kings.xlsx | C152: BLK-1CH-019-01 | D152: CRS-1CH-019 | E152: 1 | F152: 1 Chronicles | G152: 23-27 | H152: Primary Account | I152: Yes | J152: Yes | K152: Yes | L152: High | M152: Probable | N152: New main-spine bridge | P152: Primary account | Q152: SRC-TEXT-1CHR; SRC-CHRONICLES-OVERVIEW; SRC-CHRONICLES-BP | R152: Needs Review | S152: Canonical-scope block for Levites, priests, musicians, gatekeepers, officials, and military divisions.
A153: v0.2 | B153: Bible_Journey_Canon_Map_v0_2_Chronicles_Psalms_Job_1Kings.xlsx | C153: BLK-1CH-020-01 | D153: CRS-1CH-020 | E153: 1 | F153: 1 Chronicles | G153: 28-29 | H153: Complementary Account | I153: Yes | J153: Yes | K153: Yes | L153: High | M153: Probable | N153: New main-spine bridge | O153: CRS-1KG-001; CRS-1KG-002 | P153: Complementary Account | Q153: SRC-TEXT-1CHR; SRC-CHRONICLES-OVERVIEW; SRC-CHRONICLES-BP | R153: Needs Review | S153: Canonical-scope block for David's final assembly, temple charge, and Solomon's succession.
A154: v0.2 | B154: Bible_Journey_Canon_Map_v0_2_Chronicles_Psalms_Job_1Kings.xlsx | C154: BLK-1KG-001-01 | D154: CRS-1KG-001 | E154: 1 | F154: 1 Kings | G154: 1 | H154: Primary Account | I154: Yes | J154: Yes | K154: Yes | L154: High | M154: High | N154: New main-spine continuation | P154: Primary account | Q154: SRC-TEXT-1KGS; SRC-KINGS-OVERVIEW; SRC-KINGS-BP; SRC-SOLOMON-OVERVIEW; SRC-DIVIDED-MONARCHY | R154: Needs Review | S154: Canonical-scope block for Adonijah's bid and Solomon's accession.
A155: v0.2 | B155: Bible_Journey_Canon_Map_v0_2_Chronicles_Psalms_Job_1Kings.xlsx | C155: BLK-1KG-002-01 | D155: CRS-1KG-002 | E155: 1 | F155: 1 Kings | G155: 2 | H155: Primary Account | I155: Yes | J155: Yes | K155: Yes | L155: High | M155: High | N155: New main-spine continuation | P155: Primary account | Q155: SRC-TEXT-1KGS; SRC-KINGS-OVERVIEW; SRC-KINGS-BP; SRC-SOLOMON-OVERVIEW; SRC-DIVIDED-MONARCHY | R155: Needs Review | S155: Canonical-scope block for David's death and Solomon secures the throne.
A156: v0.2 | B156: Bible_Journey_Canon_Map_v0_2_Chronicles_Psalms_Job_1Kings.xlsx | C156: BLK-1KG-003-01 | D156: CRS-1KG-003 | E156: 1 | F156: 1 Kings | G156: 3 | H156: Primary Account | I156: Yes | J156: Yes | K156: Yes | L156: High | M156: High | N156: New main-spine continuation | O156: Future: 2 Chronicles 1 | P156: Primary account | Q156: SRC-TEXT-1KGS; SRC-KINGS-OVERVIEW; SRC-KINGS-BP; SRC-SOLOMON-OVERVIEW; SRC-DIVIDED-MONARCHY | R156: Needs Review | S156: Canonical-scope block for Solomon asks for wisdom at Gibeon.
A157: v0.2 | B157: Bible_Journey_Canon_Map_v0_2_Chronicles_Psalms_Job_1Kings.xlsx | C157: BLK-1KG-004-01 | D157: CRS-1KG-004 | E157: 1 | F157: 1 Kings | G157: 4 | H157: Primary Account | I157: Yes | J157: Yes | K157: Yes | L157: High | M157: High | N157: New main-spine continuation | P157: Primary account | Q157: SRC-TEXT-1KGS; SRC-KINGS-OVERVIEW; SRC-KINGS-BP; SRC-SOLOMON-OVERVIEW; SRC-DIVIDED-MONARCHY | R157: Needs Review | S157: Canonical-scope block for Solomon's administration, prosperity, and wisdom.
A158: v0.2 | B158: Bible_Journey_Canon_Map_v0_2_Chronicles_Psalms_Job_1Kings.xlsx | C158: BLK-1KG-005-01 | D158: CRS-1KG-005 | E158: 1 | F158: 1 Kings | G158: 5-6 | H158: Primary Account | I158: Yes | J158: Yes | K158: Yes | L158: High | M158: High | N158: New main-spine continuation | O158: Future: 2 Chronicles 2-3 | P158: Primary account | Q158: SRC-TEXT-1KGS; SRC-KINGS-OVERVIEW; SRC-KINGS-BP; SRC-SOLOMON-OVERVIEW; SRC-DIVIDED-MONARCHY | R158: Needs Review | S158: Canonical-scope block for Solomon builds the temple.
A159: v0.2 | B159: Bible_Journey_Canon_Map_v0_2_Chronicles_Psalms_Job_1Kings.xlsx | C159: BLK-1KG-006-01 | D159: CRS-1KG-006 | E159: 1 | F159: 1 Kings | G159: 7 | H159: Primary Account | I159: Yes | J159: Yes | K159: Yes | L159: High | M159: High | N159: New main-spine continuation | P159: Primary account | Q159: SRC-TEXT-1KGS; SRC-KINGS-OVERVIEW; SRC-KINGS-BP; SRC-SOLOMON-OVERVIEW; SRC-DIVIDED-MONARCHY | R159: Needs Review | S159: Canonical-scope block for Temple furnishings and Solomon's palace.
A160: v0.2 | B160: Bible_Journey_Canon_Map_v0_2_Chronicles_Psalms_Job_1Kings.xlsx | C160: BLK-1KG-007-01 | D160: CRS-1KG-007 | E160: 1 | F160: 1 Kings | G160: 8 | H160: Primary Account | I160: Yes | J160: Yes | K160: Yes | L160: High | M160: High | N160: New main-spine continuation | O160: Future: 2 Chronicles 5-7 | P160: Primary account | Q160: SRC-TEXT-1KGS; SRC-KINGS-OVERVIEW; SRC-KINGS-BP; SRC-SOLOMON-OVERVIEW; SRC-DIVIDED-MONARCHY | R160: Needs Review | S160: Canonical-scope block for Solomon dedicates the temple.
A161: v0.2 | B161: Bible_Journey_Canon_Map_v0_2_Chronicles_Psalms_Job_1Kings.xlsx | C161: BLK-1KG-008-01 | D161: CRS-1KG-008 | E161: 1 | F161: 1 Kings | G161: 9 | H161: Primary Account | I161: Yes | J161: Yes | K161: Yes | L161: High | M161: High | N161: New main-spine continuation | P161: Primary account | Q161: SRC-TEXT-1KGS; SRC-KINGS-OVERVIEW; SRC-KINGS-BP; SRC-SOLOMON-OVERVIEW; SRC-DIVIDED-MONARCHY | R161: Needs Review | S161: Canonical-scope block for Divine response, royal projects, and international trade.
A162: v0.2 | B162: Bible_Journey_Canon_Map_v0_2_Chronicles_Psalms_Job_1Kings.xlsx | C162: BLK-1KG-009-01 | D162: CRS-1KG-009 | E162: 1 | F162: 1 Kings | G162: 10 | H162: Primary Account | I162: Yes | J162: Yes | K162: Yes | L162: High | M162: High | N162: New main-spine continuation | O162: Future: 2 Chronicles 9 | P162: Primary account | Q162: SRC-TEXT-1KGS; SRC-KINGS-OVERVIEW; SRC-KINGS-BP; SRC-SOLOMON-OVERVIEW; SRC-DIVIDED-MONARCHY | R162: Needs Review | S162: Canonical-scope block for The queen of Sheba and Solomon's wealth.
A163: v0.2 | B163: Bible_Journey_Canon_Map_v0_2_Chronicles_Psalms_Job_1Kings.xlsx | C163: BLK-1KG-010-01 | D163: CRS-1KG-010 | E163: 1 | F163: 1 Kings | G163: 11 | H163: Primary Account | I163: Yes | J163: Yes | K163: Yes | L163: High | M163: High | N163: New main-spine continuation | P163: Primary account | Q163: SRC-TEXT-1KGS; SRC-KINGS-OVERVIEW; SRC-KINGS-BP; SRC-SOLOMON-OVERVIEW; SRC-DIVIDED-MONARCHY | R163: Needs Review | S163: Canonical-scope block for Solomon's decline and the division foretold.
...

Sheet Master Chapter Coverage
A1: MASTER CHAPTER COVERAGE
A2: Canonical audit spine across all 66 books. Each chapter has one master record; split chapters require verse-level QA before release.
A4: Canonical Key | B4: Canonical Chapter Order | C4: Testament | D4: Book Order | E4: Book | F4: Chapter | G4: Map Version | H4: Source Workbook | I4: Source Coverage Sheet | J4: Local CRS ID | K4: Local Block ID(s) | L4: Source Coverage Status | M4: Source Note / QA | N4: Source Key(s) | O4: Source Row Count | P4: Master QA
A5: Genesis 1 | B5: 1 | C5: Old Testament | D5: 1 | E5: Genesis | F5: 1 | G5: v0.1 | H5: Bible_Journey_Canon_Map_v0_1_Genesis_to_2Samuel.xlsx | I5: Chapter Map | J5: CRS-GEN-001 | L5: Mapped | O5: 1 | P5: =IF(L5="MISSING","MISSING",IF(O5=1,"PASS","DUPLICATE")) -> PASS
A6: Genesis 2 | B6: 2 | C6: Old Testament | D6: 1 | E6: Genesis | F6: 2 | G6: v0.1 | H6: Bible_Journey_Canon_Map_v0_1_Genesis_to_2Samuel.xlsx | I6: Chapter Map | J6: CRS-GEN-001 | L6: Mapped | O6: 1 | P6: =IF(L6="MISSING","MISSING",IF(O6=1,"PASS","DUPLICATE")) -> PASS
A7: Genesis 3 | B7: 3 | C7: Old Testament | D7: 1 | E7: Genesis | F7: 3 | G7: v0.1 | H7: Bible_Journey_Canon_Map_v0_1_Genesis_to_2Samuel.xlsx | I7: Chapter Map | J7: CRS-GEN-001 | L7: Mapped | O7: 1 | P7: =IF(L7="MISSING","MISSING",IF(O7=1,"PASS","DUPLICATE")) -> PASS
A8: Genesis 4 | B8: 4 | C8: Old Testament | D8: 1 | E8: Genesis | F8: 4 | G8: v0.1 | H8: Bible_Journey_Canon_Map_v0_1_Genesis_to_2Samuel.xlsx | I8: Chapter Map | J8: CRS-GEN-002 | L8: Mapped | O8: 1 | P8: =IF(L8="MISSING","MISSING",IF(O8=1,"PASS","DUPLICATE")) -> PASS
A9: Genesis 5 | B9: 5 | C9: Old Testament | D9: 1 | E9: Genesis | F9: 5 | G9: v0.1 | H9: Bible_Journey_Canon_Map_v0_1_Genesis_to_2Samuel.xlsx | I9: Chapter Map | J9: CRS-GEN-002 | L9: Mapped | O9: 1 | P9: =IF(L9="MISSING","MISSING",IF(O9=1,"PASS","DUPLICATE")) -> PASS
A10: Genesis 6 | B10: 6 | C10: Old Testament | D10: 1 | E10: Genesis | F10: 6 | G10: v0.1 | H10: Bible_Journey_Canon_Map_v0_1_Genesis_to_2Samuel.xlsx | I10: Chapter Map | J10: CRS-GEN-003 | L10: Mapped | O10: 1 | P10: =IF(L10="MISSING","MISSING",IF(O10=1,"PASS","DUPLICATE")) -> PASS
A11: Genesis 7 | B11: 7 | C11: Old Testament | D11: 1 | E11: Genesis | F11: 7 | G11: v0.1 | H11: Bible_Journey_Canon_Map_v0_1_Genesis_to_2Samuel.xlsx | I11: Chapter Map | J11: CRS-GEN-003 | L11: Mapped | O11: 1 | P11: =IF(L11="MISSING","MISSING",IF(O11=1,"PASS","DUPLICATE")) -> PASS
A12: Genesis 8 | B12: 8 | C12: Old Testament | D12: 1 | E12: Genesis | F12: 8 | G12: v0.1 | H12: Bible_Journey_Canon_Map_v0_1_Genesis_to_2Samuel.xlsx | I12: Chapter Map | J12: CRS-GEN-003 | L12: Mapped | O12: 1 | P12: =IF(L12="MISSING","MISSING",IF(O12=1,"PASS","DUPLICATE")) -> PASS
A13: Genesis 9 | B13: 9 | C13: Old Testament | D13: 1 | E13: Genesis | F13: 9 | G13: v0.1 | H13: Bible_Journey_Canon_Map_v0_1_Genesis_to_2Samuel.xlsx | I13: Chapter Map | J13: CRS-GEN-003 | L13: Mapped | O13: 1 | P13: =IF(L13="MISSING","MISSING",IF(O13=1,"PASS","DUPLICATE")) -> PASS
A14: Genesis 10 | B14: 10 | C14: Old Testament | D14: 1 | E14: Genesis | F14: 10 | G14: v0.1 | H14: Bible_Journey_Canon_Map_v0_1_Genesis_to_2Samuel.xlsx | I14: Chapter Map | J14: CRS-GEN-004 | L14: Mapped | O14: 1 | P14: =IF(L14="MISSING","MISSING",IF(O14=1,"PASS","DUPLICATE")) -> PASS
A15: Genesis 11 | B15: 11 | C15: Old Testament | D15: 1 | E15: Genesis | F15: 11 | G15: v0.1 | H15: Bible_Journey_Canon_Map_v0_1_Genesis_to_2Samuel.xlsx | I15: Chapter Map | J15: CRS-GEN-004 | L15: Mapped | O15: 1 | P15: =IF(L15="MISSING","MISSING",IF(O15=1,"PASS","DUPLICATE")) -> PASS
A16: Genesis 12 | B16: 12 | C16: Old Testament | D16: 1 | E16: Genesis | F16: 12 | G16: v0.1 | H16: Bible_Journey_Canon_Map_v0_1_Genesis_to_2Samuel.xlsx | I16: Chapter Map | J16: CRS-GEN-005 | L16: Mapped | O16: 1 | P16: =IF(L16="MISSING","MISSING",IF(O16=1,"PASS","DUPLICATE")) -> PASS
... A297: 1 Kings 2 | B297: 293 | C297: Old Testament | D297: 11 | E297: 1 Kings | F297: 2 | G297: v0.2 | H297: Bible_Journey_Canon_Map_v0_2_Chronicles_Psalms_Job_1Kings.xlsx | I297: Chapter Map | J297: CRS-1KG-002 | L297: Mapped | O297: 1 | P297: =IF(L297="MISSING","MISSING",IF(O297=1,"PASS","DUPLICATE")) -> PASS
A298: 1 Kings 3 | B298: 294 | C298: Old Testament | D298: 11 | E298: 1 Kings | F298: 3 | G298: v0.2 | H298: Bible_Journey_Canon_Map_v0_2_Chronicles_Psalms_Job_1Kings.xlsx | I298: Chapter Map | J298: CRS-1KG-003 | L298: Mapped | M298: Future: 2 Chronicles 1 | O298: 1 | P298: =IF(L298="MISSING","MISSING",IF(O298=1,"PASS","DUPLICATE")) -> PASS
A299: 1 Kings 4 | B299: 295 | C299: Old Testament | D299: 11 | E299: 1 Kings | F299: 4 | G299: v0.2 | H299: Bible_Journey_Canon_Map_v0_2_Chronicles_Psalms_Job_1Kings.xlsx | I299: Chapter Map | J299: CRS-1KG-004 | L299: Mapped | O299: 1 | P299: =IF(L299="MISSING","MISSING",IF(O299=1,"PASS","DUPLICATE")) -> PASS
A300: 1 Kings 5 | B300: 296 | C300: Old Testament | D300: 11 | E300: 1 Kings | F300: 5 | G300: v0.2 | H300: Bible_Journey_Canon_Map_v0_2_Chronicles_Psalms_Job_1Kings.xlsx | I300: Chapter Map | J300: CRS-1KG-005 | L300: Mapped | M300: Future: 2 Chronicles 2-3 | O300: 1 | P300: =IF(L300="MISSING","MISSING",IF(O300=1,"PASS","DUPLICATE")) -> PASS
A301: 1 Kings 6 | B301: 297 | C301: Old Testament | D301: 11 | E301: 1 Kings | F301: 6 | G301: v0.2 | H301: Bible_Journey_Canon_Map_v0_2_Chronicles_Psalms_Job_1Kings.xlsx | I301: Chapter Map | J301: CRS-1KG-005 | L301: Mapped | M301: Future: 2 Chronicles 2-3 | O301: 1 | P301: =IF(L301="MISSING","MISSING",IF(O301=1,"PASS","DUPLICATE")) -> PASS
A302: 1 Kings 7 | B302: 298 | C302: Old Testament | D302: 11 | E302: 1 Kings | F302: 7 | G302: v0.2 | H302: Bible_Journey_Canon_Map_v0_2_Chronicles_Psalms_Job_1Kings.xlsx | I302: Chapter Map | J302: CRS-1KG-006 | L302: Mapped | O302: 1 | P302: =IF(L302="MISSING","MISSING",IF(O302=1,"PASS","DUPLICATE")) -> PASS
A303: 1 Kings 8 | B303: 299 | C303: Old Testament | D303: 11 | E303: 1 Kings | F303: 8 | G303: v0.2 | H303: Bible_Journey_Canon_Map_v0_2_Chronicles_Psalms_Job_1Kings.xlsx | I303: Chapter Map | J303: CRS-1KG-007 | L303: Mapped | M303: Future: 2 Chronicles 5-7 | O303: 1 | P303: =IF(L303="MISSING","MISSING",IF(O303=1,"PASS","DUPLICATE")) -> PASS
A304: 1 Kings 9 | B304: 300 | C304: Old Testament | D304: 11 | E304: 1 Kings | F304: 9 | G304: v0.2 | H304: Bible_Journey_Canon_Map_v0_2_Chronicles_Psalms_Job_1Kings.xlsx | I304: Chapter Map | J304: CRS-1KG-008 | L304: Mapped | O304: 1 | P304: =IF(L304="MISSING","MISSING",IF(O304=1,"PASS","DUPLICATE")) -> PASS
A305: 1 Kings 10 | B305: 301 | C305: Old Testament | D305: 11 | E305: 1 Kings | F305: 10 | G305: v0.2 | H305: Bible_Journey_Canon_Map_v0_2_Chronicles_Psalms_Job_1Kings.xlsx | I305: Chapter Map | J305: CRS-1KG-009 | L305: Mapped | M305: Future: 2 Chronicles 9 | O305: 1 | P305: =IF(L305="MISSING","MISSING",IF(O305=1,"PASS","DUPLICATE")) -> PASS
A306: 1 Kings 11 | B306: 302 | C306: Old Testament | D306: 11 | E306: 1 Kings | F306: 11 | G306: v0.2 | H306: Bible_Journey_Canon_Map_v0_2_Chronicles_Psalms_Job_1Kings.xlsx | I306: Chapter Map | J306: CRS-1KG-010 | L306: Mapped | O306: 1 | P306: =IF(L306="MISSING","MISSING",IF(O306=1,"PASS","DUPLICATE")) -> PASS
A307: 1 Kings 12 | B307: 303 | C307: Old Testament | D307: 11 | E307: 1 Kings | F307: 12 | G307: v0.2 | H307: Bible_Journey_Canon_Map_v0_2_Chronicles_Psalms_Job_1Kings.xlsx | I307: Chapter Map | J307: CRS-1KG-011 | L307: Mapped | M307: Future: 2 Chronicles 10 | O307: 1 | P307: =IF(L307="MISSING","MISSING",IF(O307=1,"PASS","DUPLICATE")) -> PASS
A308: 1 Kings 13 | B308: 304 | C308: Old Testament | D308: 11 | E308: 1 Kings | F308: 13 | G308: v0.2 | H308: Bible_Journey_Canon_Map_v0_2_Chronicles_Psalms_Job_1Kings.xlsx | I308: Chapter Map | J308: CRS-1KG-012 | L308: Mapped | O308: 1 | P308: =IF(L308="MISSING","MISSING",IF(O308=1,"PASS","DUPLICATE")) -> PASS
A309: 1 Kings 14 | B309: 305 | C309: Old Testament | D309: 11 | E309: 1 Kings | F309: 14 | G309: v0.2 | H309: Bible_Journey_Canon_Map_v0_2_Chronicles_Psalms_Job_1Kings.xlsx | I309: Chapter Map | J309: CRS-1KG-013 | L309: Mapped | M309: Future: 2 Chronicles 12 | O309: 1 | P309: =IF(L309="MISSING","MISSING",IF(O309=1,"PASS","DUPLICATE")) -> PASS
A310: 1 Kings 15 | B310: 306 | C310: Old Testament | D310: 11 | E310: 1 Kings | F310: 15 | G310: v0.2 | H310: Bible_Journey_Canon_Map_v0_2_Chronicles_Psalms_Job_1Kings.xlsx | I310: Chapter Map | J310: CRS-1KG-014 | L310: Mapped | M310: Future: 2 Chronicles 13-16 | O310: 1 | P310: =IF(L310="MISSING","MISSING",IF(O310=1,"PASS","DUPLICATE")) -> PASS
A311: 1 Kings 16 | B311: 307 | C311: Old Testament | D311: 11 | E311: 1 Kings | F311: 16 | G311: v0.2 | H311: Bible_Journey_Canon_Map_v0_2_Chronicles_Psalms_Job_1Kings.xlsx | I311: Chapter Map | J311: CRS-1KG-015 | L311: Mapped | O311: 1 | P311: =IF(L311="MISSING","MISSING",IF(O311=1,"PASS","DUPLICATE")) -> PASS
A312: 1 Kings 17 | B312: 308 | C312: Old Testament | D312: 11 | E312: 1 Kings | F312: 17 | G312: v0.2 | H312: Bible_Journey_Canon_Map_v0_2_Chronicles_Psalms_Job_1Kings.xlsx | I312: Chapter Map | J312: CRS-1KG-016 | L312: Mapped | O312: 1 | P312: =IF(L312="MISSING","MISSING",IF(O312=1,"PASS","DUPLICATE")) -> PASS
A313: 1 Kings 18 | B313: 309 | C313: Old Testament | D313: 11 | E313: 1 Kings | F313: 18 | G313: v0.2 | H313: Bible_Journey_Canon_Map_v0_2_Chronicles_Psalms_Job_1Kings.xlsx | I313: Chapter Map | J313: CRS-1KG-017 | L313: Mapped | O313: 1 | P313: =IF(L313="MISSING","MISSING",IF(O313=1,"PASS","DUPLICATE")) -> PASS
A314: 1 Kings 19 | B314: 310 | C314: Old Testament | D314: 11 | E314: 1 Kings | F314: 19 | G314: v0.2 | H314: Bible_Journey_Canon_Map_v0_2_Chronicles_Psalms_Job_1Kings.xlsx | I314: Chapter Map | J314: CRS-1KG-018 | L314: Mapped | O314: 1 | P314: =IF(L314="MISSING","MISSING",IF(O314=1,"PASS","DUPLICATE")) -> PASS
A315: 1 Kings 20 | B315: 311 | C315: Old Testament | D315: 11 | E315: 1 Kings | F315: 20 | G315: v0.2 | H315: Bible_Journey_Canon_Map_v0_2_Chronicles_Psalms_Job_1Kings.xlsx | I315: Chapter Map | J315: CRS-1KG-019 | L315: Mapped | O315: 1 | P315: =IF(L315="MISSING","MISSING",IF(O315=1,"PASS","DUPLICATE")) -> PASS
A316: 1 Kings 21 | B316: 312 | C316: Old Testament | D316: 11 | E316: 1 Kings | F316: 21 | G316: v0.2 | H316: Bible_Journey_Canon_Map_v0_2_Chronicles_Psalms_Job_1Kings.xlsx | I316: Chapter Map | J316: CRS-1KG-020 | L316: Mapped | O316: 1 | P316: =IF(L316="MISSING","MISSING",IF(O316=1,"PASS","DUPLICATE")) -> PASS
A317: 1 Kings 22 | B317: 313 | C317: Old Testament | D317: 11 | E317: 1 Kings | F317: 22 | G317: v0.2 | H317: Bible_Journey_Canon_Map_v0_2_Chronicles_Psalms_Job_1Kings.xlsx | I317: Chapter Map | J317: CRS-1KG-021 | L317: Mapped | M317: Future: 2 Chronicles 18 | O317: 1 | P317: =IF(L317="MISSING","MISSING",IF(O317=1,"PASS","DUPLICATE")) -> PASS
A318: 2 Kings 1 | B318: 314 | C318: Old Testament | D318: 12 | E318: 2 Kings | F318: 1 | G318: v0.3 | H318: Bible_Journey_Canon_Map_v0_3_2Chronicles_Wisdom_2Kings.xlsx | I318: Chapter Map | J318: CRS-2K-001 | L318: Mapped | M318: Ahaziah's inquiry and Elijah's judgment. No Chronicles parallel. | O318: 1 | P318: =IF(L318="MISSING","MISSING",IF(O318=1,"PASS","DUPLICATE")) -> PASS
A319: 2 Kings 2 | B319: 315 | C319: Old Testament | D319: 12 | E319: 2 Kings | F319: 2 | G319: v0.3 | H319: Bible_Journey_Canon_Map_v0_3_2Chronicles_Wisdom_2Kings.xlsx | I319: Chapter Map | J319: CRS-2K-002 | L319: Mapped | M319: Elijah's departure and the public transition to Elisha. | O319: 1 | P319: =IF(L319="MISSING","MISSING",IF(O319=1,"PASS","DUPLICATE")) -> PASS
A320: 2 Kings 3 | B320: 316 | C320: Old Testament | D320: 12 | E320: 2 Kings | F320: 3 | G320: v0.3 | H320: Bible_Journey_Canon_Map_v0_3_2Chronicles_Wisdom_2Kings.xlsx | I320: Chapter Map | J320: CRS-2K-003 | L320: Mapped | M320: A coalition campaign narrated through the role of Elisha. | O320: 1 | P320: =IF(L320="MISSING","MISSING",IF(O320=1,"PASS","DUPLICATE")) -> PASS
A321: 2 Kings 4 | B321: 317 | C321: Old Testament | D321: 12 | E321: 2 Kings | F321: 4 | G321: v0.3 | H321: Bible_Journey_Canon_Map_v0_3_2Chronicles_Wisdom_2Kings.xlsx | I321: Chapter Map | J321: CRS-2K-004 | L321: Mapped | M321: A linked cycle of Elisha narratives; retain as one canonical chapter for the first mapping pass. | O321: 1 | P321: =IF(L321="MISSING","MISSING",IF(O321=1,"PASS","DUPLICATE")) -> PASS
...

Sheet Book Catalog
A1: BOOK CATALOG
